Workbook

Sheet Cover
A1: VARUN BEVERAGES LIMITED
A6: Discounted Cash Flow (DCF) Valuation Model
B10: Sector: | D10: FMCG - Beverages
B11: Exchange: | D11: NSE (National Stock Exchange)
B12: Currency: | D12: ₹ Indian Rupees (Crore)
B13: Fiscal Year End: | D13: 41030
B14: Model Date: | D14: 2026
B15: Analyst: | D15: Bhavook Wadhwa

Sheet Assumptions
A1: Compounded Sales Growth | B1: %
A2: 10 Years: | B2: 0.2
A3: 5 Years: | B3: 0.27
A4: 3 Years: | B4: 0.18
A5: TTM: | B5: 0.14
A6: Operating Blocks | C6: Dec-26E | D6: Dec-27E | E6: Dec-28E | F6: Dec-29E | G6: Dec-30E | H6: Dec-31E | I6: Dec-32E | J6: Dec-33E | K6: Dec-34E | L6: Dec-35E
A7: Sales Growth Rate | C7: 0.185 | D7: 0.195 | E7: 0.2 | F7: 0.205 | G7: 0.19 | H7: 0.175 | I7: 0.16 | J7: 0.145 | K7: 0.12 | L7: 0.1
A8: EBITDA Margin | C8: 0.23 | D8: 0.235 | E8: 0.24 | F8: 0.245 | G8: 0.25 | H8: 0.24 | I8: 0.23 | J8: 0.23 | K8: 0.22 | L8: 0.22
A9: CapEx As % of Sales | C9: 0.14 | D9: 0.16 | E9: 0.17 | F9: 0.18 | G9: 0.14 | H9: 0.13 | I9: 0.11 | J9: 0.09 | K9: 0.07 | L9: 0.05
A10: Dep. As % of Sales | C10: 0.05 | D10: 0.05 | E10: 0.055 | F10: 0.055 | G10: 0.05 | H10: 0.05 | I10: 0.05 | J10: 0.045 | K10: 0.045 | L10: 0.045
A11: NWC As % of Sales | C11: 0.12 | D11: 0.105 | E11: 0.09 | F11: 0.075 | G11: 0.06 | H11: 0.055 | I11: 0.05 | J11: 0.045 | K11: 0.04 | L11: 0.04
A12: WACC Assumptions
A13: Risk Free Rate Rf | B13: 0.0695
A14: Equity Risk Premium (ERP) | B14: 0.0708
A15: Beta (b) | B15: 1.05
A17: Cost of Equity (Ke) | B17: =(B13+(B14*B15))*100 -> 14.384
A18: Cost of Debt (Kd)
A19: Pre-Tax Cost of Debt: | B19: ='Income Statement Working'!D9/'Net Working Capital'!D18 -> 0.096837945
A20: Post-Tax Cost of Debt: | B20: =(B19*(1-0.24))*100 -> 7.3596838
A22: Market Cap. | B22: 169488
A23: Total Capital (Market Cap. + Debt) | B23: =B22+'Net Working Capital'!D18 -> 171512
A25: Weight of Equity | B25: =B22/B23 -> 0.98819908
A26: Weight of Debt | B26: ='Net Working Capital'!D18/Assumptions!B23 -> 0.011800924
A28: WACC | B28: =(B17*B25)+(B20*B26) -> 14.301107 | C28: =B28/100 -> 0.14301107

Sheet Income Statement Working
A1: Particulars | B1: 45261 | C1: 45627 | D1: 45992 | E1: Dec-26E | F1: Dec-27E | G1: Dec-28E | H1: Dec-29E | I1: Dec-30E | J1: Dec-31E | K1: Dec-32E | L1: Dec-33E | M1: Dec-34E | N1: Dec-35E
A2: Sales | B2: 16043 | C2: 20008 | D2: 21685 | E2: =D2*(1+Assumptions!C7) -> 25696.725 | F2: =E2*(1+Assumptions!D7) -> 30707.586 | G2: =F2*(1+Assumptions!E7) -> 36849.104 | H2: =G2*(1+Assumptions!F7) -> 44403.17 | I2: =H2*(1+Assumptions!G7) -> 52839.772 | J2: =I2*(1+Assumptions!H7) -> 62086.732 | K2: =J2*(1+Assumptions!I7) -> 72020.609 | L2: =K2*(1+Assumptions!J7) -> 82463.598 | ... N2: =M2*(1+Assumptions!L7) -> 101595.15
A3: Material Cost | B3: =B2*(46.16/100) -> 7405.4488 | C3: =C2*(44.51/100) -> 8905.5608 | D3: =D2*(44.8/100) -> 9714.88
A4: Employee Cost | B4: =B2*(9.02/100) -> 1447.0786 | C4: =C2*(9.43/100) -> 1886.7544 | D4: =D2*(10.15/100) -> 2201.0275
A5: Other Operating Expenses | B5: =B2*((14.87+6.78)/100) -> 3473.3095 | C5: =C2*((15.44+6.55)/100) -> 4399.7592 | D5: =D2*((6.02+15.65)/100) -> 4699.1395
A6: EBITDA | B6: =B2-(B3+B4+B5) -> 3717.1631 | C6: =C2-(C3+C4+C5) -> 4815.9256 | D6: =D2-(D3+D4+D5) -> 5069.953 | E6: =E2*Assumptions!C8 -> 5910.2468 | F6: =F2*Assumptions!D8 -> 7216.2828 | G6: =G2*Assumptions!E8 -> 8843.7849 | H6: =H2*Assumptions!F8 -> 10878.777 | I6: =I2*Assumptions!G8 -> 13209.943 | J6: =J2*Assumptions!H8 -> 14900.816 | K6: =K2*Assumptions!I8 -> 16564.74 | L6: =L2*Assumptions!J8 -> 18966.628 | ... N6: =N2*Assumptions!L8 -> 22350.934
A7: Depreciation | B7: 681 | C7: 947 | D7: 1216 | E7: =E2*Assumptions!C10 -> 1284.8363 | F7: =F2*Assumptions!D10 -> 1535.3793 | G7: =G2*Assumptions!E10 -> 2026.7007 | H7: =H2*Assumptions!F10 -> 2442.1743 | I7: =I2*Assumptions!G10 -> 2641.9886 | J7: =J2*Assumptions!H10 -> 3104.3366 | K7: =K2*Assumptions!I10 -> 3601.0305 | L7: =L2*Assumptions!J10 -> 3710.8619 | ... N7: =N2*Assumptions!L10 -> 4571.7819
A8: EBIT | B8: =B6-B7 -> 3036.1631 | C8: =C6-C7 -> 3868.9256 | D8: =D6-D7 -> 3853.953 | E8: =E6-E7 -> 4625.4105 | F8: =F6-F7 -> 5680.9035 | G8: =G6-G7 -> 6817.0842 | H8: =H6-H7 -> 8436.6023 | I8: =I6-I7 -> 10567.954 | ... N8: =N6-N7 -> 17779.152
A9: Interest | B9: 292 | C9: 483 | D9: 196
A10: PBT | B10: =B8-B9 -> 2744.1631 | C10: =C8-C9 -> 3385.9256 | D10: =D8-D9 -> 3657.953
A11: Tax | B11: =B10*(23/100) -> 631.15751 | C11: =C10*(23/100) -> 778.76289 | D11: =D10*(24/100) -> 877.90872 | E11: =E8*(24/100) -> 1110.0985 | F11: =F8*(24/100) -> 1363.4168 | G11: =G8*(24/100) -> 1636.1002 | H11: =H8*(24/100) -> 2024.7845 | I11: =I8*(24/100) -> 2536.3091 | J11: =J8*(24/100) -> 2831.155 | K11: =K8*(24/100) -> 3111.2903 | L11: =L8*(24/100) -> 3661.3837 | ... N11: =N8*(24/100) -> 4266.9964
A12: PAT | B12: =B10-B11 -> 2113.0056 | C12: =C10-C11 -> 2607.1627 | D12: =D10-D11 -> 2780.0443
A13: NOPAT | E13: =E8-E11 -> 3515.312 | F13: =F8-F11 -> 4317.4866 | G13: =G8-G11 -> 5180.984 | H13: =H8-H11 -> 6411.8177 | I13: =I8-I11 -> 8031.6454 | J13: =J8-J11 -> 8965.3241 | K13: =K8-K11 -> 9852.4194 | L13: =L8-L11 -> 11594.382 | ... N13: =N8-N11 -> 13512.155
A14: EBITDA Margin | B14: =(B6/B2)*100 -> 23.17 | C14: =(C6/C2)*100 -> 24.07 | D14: =(D6/D2)*100 -> 23.38 | E14: =(E6/E2)*100 -> 23 | F14: =(F6/F2)*100 -> 23.5 | G14: =(G6/G2)*100 -> 24 | H14: =(H6/H2)*100 -> 24.5 | I14: =(I6/I2)*100 -> 25 | ... N14: =(N6/N2)*100 -> 22
A15: Dep Margin | B15: =(B7/B2)*100 -> 4.244842 | C15: =(C7/C2)*100 -> 4.7331068 | D15: =(D7/D2)*100 -> 5.6075628 | E15: =(E7/E2)*100 -> 5 | F15: =(F7/F2)*100 -> 5 | G15: =(G7/G2)*100 -> 5.5 | H15: =(H7/H2)*100 -> 5.5 | I15: =(I7/I2)*100 -> 5 | ... N15: =(N7/N2)*100 -> 4.5
A16: Sales Margin | D16: =(D2-C2)/C2*100 -> 8.3816473 | E16: =(E2-D2)/D2*100 -> 18.5 | F16: =(F2-E2)/E2*100 -> 19.5 | G16: =(G2-F2)/F2*100 -> 20 | H16: =(H2-G2)/G2*100 -> 20.5 | I16: =(I2-H2)/H2*100 -> 19 | J16: =(J2-I2)/I2*100 -> 17.5 | K16: =(K2-J2)/J2*100 -> 16 | ... N16: =(N2-M2)/M2*100 -> 10
A17: ETR
A18: The Historical Anchor | B18: =B11/B10 -> 0.23 | C18: =C11/C10 -> 0.23 | D18: =D11/D10 -> 0.24 | E18: 0.24 | F18: 0.24 | G18: 0.24 | H18: 0.24 | I18: 0.24 | J18: 0.24 | K18: 0.24 | L18: 0.24 | M18: 0.24 | N18: 0.24

Sheet Free Cash Flow Build
A1: Particulars | B1: 45261 | C1: 45627 | D1: 45992 | E1: Dec-26E | F1: Dec-27E | G1: Dec-28E | H1: Dec-29E | I1: Dec-30E | J1: Dec-31E | K1: Dec-32E | L1: Dec-33E | M1: Dec-34E | N1: Dec-35E
A2: EBIT(Operations Profit) | B2: 3036.1631 | C2: 3868.9256 | D2: 3853.953
A3: Less: Adjusted Tax | B3: =B2*(23/100) -> 698.31751 | C3: =C2*(23/100) -> 889.85289 | D3: =D2*(24/100) -> 924.94872
A4: NOPAT | B4: =B2-B3 -> 2337.8456 | C4: =C2-C3 -> 2979.0727 | D4: =D2-D3 -> 2929.0043 | E4: ='Income Statement Working'!E8-'Income Statement Working'!E11 -> 3515.312 | F4: ='Income Statement Working'!F8-'Income Statement Working'!F11 -> 4317.4866 | G4: ='Income Statement Working'!G8-'Income Statement Working'!G11 -> 5180.984 | H4: ='Income Statement Working'!H8-'Income Statement Working'!H11 -> 6411.8177 | I4: ='Income Statement Working'!I8-'Income Statement Working'!I11 -> 8031.6454 | J4: ='Income Statement Working'!J8-'Income Statement Working'!J11 -> 8965.3241 | K4: ='Income Statement Working'!K8-'Income Statement Working'!K11 -> 9852.4194 | L4: ='Income Statement Working'!L8-'Income Statement Working'!L11 -> 11594.382 | ... N4: ='Income Statement Working'!N8-'Income Statement Working'!N11 -> 13512.155
A5: Add: DEP & AMT | B5: 681 | C5: 947 | D5: 1216 | E5: ='Income Statement Working'!E2*Assumptions!C10 -> 1284.8363 | F5: ='Income Statement Working'!F2*Assumptions!D10 -> 1535.3793 | G5: ='Income Statement Working'!G2*Assumptions!E10 -> 2026.7007 | H5: ='Income Statement Working'!H2*Assumptions!F10 -> 2442.1743 | I5: ='Income Statement Working'!I2*Assumptions!G10 -> 2641.9886 | J5: ='Income Statement Working'!J2*Assumptions!H10 -> 3104.3366 | K5: ='Income Statement Working'!K2*Assumptions!I10 -> 3601.0305 | L5: ='Income Statement Working'!L2*Assumptions!J10 -> 3710.8619 | ... N5: ='Income Statement Working'!N2*Assumptions!L10 -> 4571.7819
A6: Less: Cap Exp | B6: 3264 | C6: 3779 | D6: 2739 | E6: ='Income Statement Working'!E2*Assumptions!C9 -> 3597.5415 | F6: ='Income Statement Working'!F2*Assumptions!D9 -> 4913.2138 | G6: ='Income Statement Working'!G2*Assumptions!E9 -> 6264.3476 | H6: ='Income Statement Working'!H2*Assumptions!F9 -> 7992.5706 | I6: ='Income Statement Working'!I2*Assumptions!G9 -> 7397.5681 | J6: ='Income Statement Working'!J2*Assumptions!H9 -> 8071.2752 | K6: ='Income Statement Working'!K2*Assumptions!I9 -> 7922.267 | L6: ='Income Statement Working'!L2*Assumptions!J9 -> 7421.7238 | ... N6: ='Income Statement Working'!N2*Assumptions!L9 -> 5079.7576
A7: Less: Changes in NWC | B7: 0 | C7: 748 | D7: 559 | E7: ='Net Working Capital'!E13-'Net Working Capital'!D13 -> 36.607 | F7: ='Net Working Capital'!F13-'Net Working Capital'!E13 -> 140.68957 | G7: ='Net Working Capital'!G13-'Net Working Capital'!F13 -> 92.122759 | H7: ='Net Working Capital'!H13-'Net Working Capital'!G13 -> 13.818414 | I7: ='Net Working Capital'!I13-'Net Working Capital'!H13 -> -159.85141 | J7: ='Net Working Capital'!J13-'Net Working Capital'!I13 -> 244.38395 | K7: ='Net Working Capital'!K13-'Net Working Capital'!J13 -> 186.2602 | L7: ='Net Working Capital'!L13-'Net Working Capital'!K13 -> 109.83143 | ... N7: ='Net Working Capital'!N13-'Net Working Capital'!M13 -> 369.43692
A8: Unlevered Free Cash Flow | B8: =B4+B5-B6-B7 -> -245.15441 | C8: =C4+C5-C6-C7 -> -600.92729 | D8: =D4+D5-D6-D7 -> 847.00428 | E8: =E4+E5-E6-E7 -> 1165.9997 | F8: =F4+F5-F6-F7 -> 798.96257 | G8: =G4+G5-G6-G7 -> 851.21429 | H8: =H4+H5-H6-H7 -> 847.60308 | I8: =I4+I5-I6-I7 -> 3435.9173 | ... N8: =N4+N5-N6-N7 -> 12634.743
A10: Cap Ex Margin | D10: =D6/'Income Statement Working'!D2 -> 0.12630851 | E10: =E6/'Income Statement Working'!E2 -> 0.14 | F10: =F6/'Income Statement Working'!F2 -> 0.16 | G10: =G6/'Income Statement Working'!G2 -> 0.17 | H10: =H6/'Income Statement Working'!H2 -> 0.18 | I10: =I6/'Income Statement Working'!I2 -> 0.14 | J10: =J6/'Income Statement Working'!J2 -> 0.13 | K10: =K6/'Income Statement Working'!K2 -> 0.11 | ... N10: =N6/'Income Statement Working'!N2 -> 0.05
A12: Discounting Factor | E12: =(1+(Assumptions!$B$28/100))^1 -> 1.1430111 | F12: =(1+(Assumptions!$B$28/100))^2 -> 1.3064743 | G12: =(1+(Assumptions!$B$28/100))^3 -> 1.4933146 | H12: =(1+(Assumptions!$B$28/100))^4 -> 1.7068751 | I12: =(1+(Assumptions!$B$28/100))^5 -> 1.9509771 | J12: =(1+(Assumptions!$B$28/100))^6 -> 2.2299884 | K12: =(1+(Assumptions!$B$28/100))^7 -> 2.5489015 | L12: =(1+(Assumptions!$B$28/100))^8 -> 2.9134226 | M12: =(1+(Assumptions!$B$28/100))^9 -> 3.3300742 | N12: =(1+(Assumptions!$B$28/100))^10 -> 3.8063117
A13: Present Value (PV) of UFCF | E13: =E8/E12 -> 1020.1124 | F13: =F8/F12 -> 611.54098 | G13: =G8/G12 -> 570.01673 | H13: =H8/H12 -> 496.58179 | I13: =I8/I12 -> 1761.1264 | J13: =J8/J12 -> 1683.4175 | K13: =K8/K12 -> 2096.9515 | L13: =L8/L12 -> 2668.2324 | ... N13: =N8/N12 -> 3319.4188
A14: Terminal Growth Rate | N14: 0.05 | O14: 0.05
A15: Terminal Value | N15: =(N8*(1+0.05))/(Assumptions!C28-'Free Cash Flow Build'!O14) -> 142633.35
A16: Present Value (PV) of TV | N16: =N15/N12 -> 37472.85
A18: Enterprise Value | N18: =SUM(E13:N13)+N16 -> 54700.569
A19: Borrowings/Total Debt | D19: =SUM(540+1484) -> 2024
A20: C&CE | D20: 1998
A21: Equity Value | N21: =(N18+D20)-(D19) -> 54674.569
A23: No. of Shares Outstanding | N23: 338.2
A24: Intrinsic Target Share Price | N24: =N21/N23 -> 161.66342
A26: Market Share Price (03-09-2026) | N26: 407
A28: Margin of Safety | O28: =(N24-N26)/N24 -> -1.5175763 | P28: I focus on identifying intrinsic value with a strict emphasis on the Margin of Safety.

Sheet Sensitivity Analysis
A1: Sensitivity Analysis
A2: Two-way sensitivity of the DCF output to the Weighted Average Cost of Capital (WACC) and the Terminal Growth Rate, built from the same unlevered free cash flows as the Free Cash Flow Build sheet.
A4: TABLE 1 — INTRINSIC VALUE PER SHARE (₹)
B6: Terminal Growth (g) ↓ / WACC → | C6: =Assumptions!$C$28-0.01 -> 0.13301107 | D6: =Assumptions!$C$28-0.005 -> 0.13801107 | E6: =Assumptions!$C$28 -> 0.14301107 | F6: =Assumptions!$C$28+0.005 -> 0.14801107 | G6: =Assumptions!$C$28+0.01 -> 0.15301107
B7: ='Free Cash Flow Build'!$O$14-0.01 -> 0.04 | C7: =((SUMPRODUCT('Free Cash Flow Build'!$E$8:$N$8,(1+C$6)^-{1,2,3,4,5,6,7,8,9,10})+(('Free Cash Flow Build'!$N$8*(1+$B7))/(C$6-$B7))/(1+C$6)^10)+'Free Cash Flow Build'!$D$20-'Free Cash Flow Build'!$D$19)/'Free Cash Flow Build'!$N$23 -> 173.94741 | D7: =((SUMPRODUCT('Free Cash Flow Build'!$E$8:$N$8,(1+D$6)^-{1,2,3,4,5,6,7,8,9,10})+(('Free Cash Flow Build'!$N$8*(1+$B7))/(D$6-$B7))/(1+D$6)^10)+'Free Cash Flow Build'!$D$20-'Free Cash Flow Build'!$D$19)/'Free Cash Flow Build'!$N$23 -> 161.27418 | E7: =((SUMPRODUCT('Free Cash Flow Build'!$E$8:$N$8,(1+E$6)^-{1,2,3,4,5,6,7,8,9,10})+(('Free Cash Flow Build'!$N$8*(1+$B7))/(E$6-$B7))/(1+E$6)^10)+'Free Cash Flow Build'!$D$20-'Free Cash Flow Build'!$D$19)/'Free Cash Flow Build'!$N$23 -> 149.95441 | F7: =((SUMPRODUCT('Free Cash Flow Build'!$E$8:$N$8,(1+F$6)^-{1,2,3,4,5,6,7,8,9,10})+(('Free Cash Flow Build'!$N$8*(1+$B7))/(F$6-$B7))/(1+F$6)^10)+'Free Cash Flow Build'!$D$20-'Free Cash Flow Build'!$D$19)/'Free Cash Flow Build'!$N$23 -> 139.79547 | G7: =((SUMPRODUCT('Free Cash Flow Build'!$E$8:$N$8,(1+G$6)^-{1,2,3,4,5,6,7,8,9,10})+(('Free Cash Flow Build'!$N$8*(1+$B7))/(G$6-$B7))/(1+G$6)^10)+'Free Cash Flow Build'!$D$20-'Free Cash Flow Build'!$D$19)/'Free Cash Flow Build'!$N$23 -> 130.63904
B8: ='Free Cash Flow Build'!$O$14-0.005 -> 0.045 | C8: =((SUMPRODUCT('Free Cash Flow Build'!$E$8:$N$8,(1+C$6)^-{1,2,3,4,5,6,7,8,9,10})+(('Free Cash Flow Build'!$N$8*(1+$B8))/(C$6-$B8))/(1+C$6)^10)+'Free Cash Flow Build'!$D$20-'Free Cash Flow Build'!$D$19)/'Free Cash Flow Build'!$N$23 -> 181.36365 | D8: =((SUMPRODUCT('Free Cash Flow Build'!$E$8:$N$8,(1+D$6)^-{1,2,3,4,5,6,7,8,9,10})+(('Free Cash Flow Build'!$N$8*(1+$B8))/(D$6-$B8))/(1+D$6)^10)+'Free Cash Flow Build'!$D$20-'Free Cash Flow Build'!$D$19)/'Free Cash Flow Build'!$N$23 -> 167.67498 | E8: =((SUMPRODUCT('Free Cash Flow Build'!$E$8:$N$8,(1+E$6)^-{1,2,3,4,5,6,7,8,9,10})+(('Free Cash Flow Build'!$N$8*(1+$B8))/(E$6-$B8))/(1+E$6)^10)+'Free Cash Flow Build'!$D$20-'Free Cash Flow Build'!$D$19)/'Free Cash Flow Build'!$N$23 -> 155.51025 | F8: =((SUMPRODUCT('Free Cash Flow Build'!$E$8:$N$8,(1+F$6)^-{1,2,3,4,5,6,7,8,9,10})+(('Free Cash Flow Build'!$N$8*(1+$B8))/(F$6-$B8))/(1+F$6)^10)+'Free Cash Flow Build'!$D$20-'Free Cash Flow Build'!$D$19)/'Free Cash Flow Build'!$N$23 -> 144.64273 | G8: =((SUMPRODUCT('Free Cash Flow Build'!$E$8:$N$8,(1+G$6)^-{1,2,3,4,5,6,7,8,9,10})+(('Free Cash Flow Build'!$N$8*(1+$B8))/(G$6-$B8))/(1+G$6)^10)+'Free Cash Flow Build'!$D$20-'Free Cash Flow Build'!$D$19)/'Free Cash Flow Build'!$N$23 -> 134.8879
B9: ='Free Cash Flow Build'!$O$14 -> 0.05 | C9: =((SUMPRODUCT('Free Cash Flow Build'!$E$8:$N$8,(1+C$6)^-{1,2,3,4,5,6,7,8,9,10})+(('Free Cash Flow Build'!$N$8*(1+$B9))/(C$6-$B9))/(1+C$6)^10)+'Free Cash Flow Build'!$D$20-'Free Cash Flow Build'!$D$19)/'Free Cash Flow Build'!$N$23 -> 189.67329 | D9: =((SUMPRODUCT('Free Cash Flow Build'!$E$8:$N$8,(1+D$6)^-{1,2,3,4,5,6,7,8,9,10})+(('Free Cash Flow Build'!$N$8*(1+$B9))/(D$6-$B9))/(1+D$6)^10)+'Free Cash Flow Build'!$D$20-'Free Cash Flow Build'!$D$19)/'Free Cash Flow Build'!$N$23 -> 174.80306 | E9: =((SUMPRODUCT('Free Cash Flow Build'!$E$8:$N$8,(1+E$6)^-{1,2,3,4,5,6,7,8,9,10})+(('Free Cash Flow Build'!$N$8*(1+$B9))/(E$6-$B9))/(1+E$6)^10)+'Free Cash Flow Build'!$D$20-'Free Cash Flow Build'!$D$19)/'Free Cash Flow Build'!$N$23 -> 161.66342 | F9: =((SUMPRODUCT('Free Cash Flow Build'!$E$8:$N$8,(1+F$6)^-{1,2,3,4,5,6,7,8,9,10})+(('Free Cash Flow Build'!$N$8*(1+$B9))/(F$6-$B9))/(1+F$6)^10)+'Free Cash Flow Build'!$D$20-'Free Cash Flow Build'!$D$19)/'Free Cash Flow Build'!$N$23 -> 149.98455 | G9: =((SUMPRODUCT('Free Cash Flow Build'!$E$8:$N$8,(1+G$6)^-{1,2,3,4,5,6,7,8,9,10})+(('Free Cash Flow Build'!$N$8*(1+$B9))/(G$6-$B9))/(1+G$6)^10)+'Free Cash Flow Build'!$D$20-'Free Cash Flow Build'!$D$19)/'Free Cash Flow Build'!$N$23 -> 139.54922
B10: ='Free Cash Flow Build'!$O$14+0.005 -> 0.055 | C10: =((SUMPRODUCT('Free Cash Flow Build'!$E$8:$N$8,(1+C$6)^-{1,2,3,4,5,6,7,8,9,10})+(('Free Cash Flow Build'!$N$8*(1+$B10))/(C$6-$B10))/(1+C$6)^10)+'Free Cash Flow Build'!$D$20-'Free Cash Flow Build'!$D$19)/'Free Cash Flow Build'!$N$23 -> 199.04812 | D10: =((SUMPRODUCT('Free Cash Flow Build'!$E$8:$N$8,(1+D$6)^-{1,2,3,4,5,6,7,8,9,10})+(('Free Cash Flow Build'!$N$8*(1+$B10))/(D$6-$B10))/(1+D$6)^10)+'Free Cash Flow Build'!$D$20-'Free Cash Flow Build'!$D$19)/'Free Cash Flow Build'!$N$23 -> 182.78983 | E10: =((SUMPRODUCT('Free Cash Flow Build'!$E$8:$N$8,(1+E$6)^-{1,2,3,4,5,6,7,8,9,10})+(('Free Cash Flow Build'!$N$8*(1+$B10))/(E$6-$B10))/(1+E$6)^10)+'Free Cash Flow Build'!$D$20-'Free Cash Flow Build'!$D$19)/'Free Cash Flow Build'!$N$23 -> 168.51573 | F10: =((SUMPRODUCT('Free Cash Flow Build'!$E$8:$N$8,(1+F$6)^-{1,2,3,4,5,6,7,8,9,10})+(('Free Cash Flow Build'!$N$8*(1+$B10))/(F$6-$B10))/(1+F$6)^10)+'Free Cash Flow Build'!$D$20-'Free Cash Flow Build'!$D$19)/'Free Cash Flow Build'!$N$23 -> 155.90069 | G10: =((SUMPRODUCT('Free Cash Flow Build'!$E$8:$N$8,(1+G$6)^-{1,2,3,4,5,6,7,8,9,10})+(('Free Cash Flow Build'!$N$8*(1+$B10))/(G$6-$B10))/(1+G$6)^10)+'Free Cash Flow Build'!$D$20-'Free Cash Flow Build'!$D$19)/'Free Cash Flow Build'!$N$23 -> 144.68614
B11: ='Free Cash Flow Build'!$O$14+0.01 -> 0.06 | C11: =((SUMPRODUCT('Free Cash Flow Build'!$E$8:$N$8,(1+C$6)^-{1,2,3,4,5,6,7,8,9,10})+(('Free Cash Flow Build'!$N$8*(1+$B11))/(C$6-$B11))/(1+C$6)^10)+'Free Cash Flow Build'!$D$20-'Free Cash Flow Build'!$D$19)/'Free Cash Flow Build'!$N$23 -> 209.70697 | D11: =((SUMPRODUCT('Free Cash Flow Build'!$E$8:$N$8,(1+D$6)^-{1,2,3,4,5,6,7,8,9,10})+(('Free Cash Flow Build'!$N$8*(1+$B11))/(D$6-$B11))/(1+D$6)^10)+'Free Cash Flow Build'!$D$20-'Free Cash Flow Build'!$D$19)/'Free Cash Flow Build'!$N$23 -> 191.8004 | E11: =((SUMPRODUCT('Free Cash Flow Build'!$E$8:$N$8,(1+E$6)^-{1,2,3,4,5,6,7,8,9,10})+(('Free Cash Flow Build'!$N$8*(1+$B11))/(E$6-$B11))/(1+E$6)^10)+'Free Cash Flow Build'!$D$20-'Free Cash Flow Build'!$D$19)/'Free Cash Flow Build'!$N$23 -> 176.19351 | F11: =((SUMPRODUCT('Free Cash Flow Build'!$E$8:$N$8,(1+F$6)^-{1,2,3,4,5,6,7,8,9,10})+(('Free Cash Flow Build'!$N$8*(1+$B11))/(F$6-$B11))/(1+F$6)^10)+'Free Cash Flow Build'!$D$20-'Free Cash Flow Build'!$D$19)/'Free Cash Flow Build'!$N$23 -> 162.48903 | G11: =((SUMPRODUCT('Free Cash Flow Build'!$E$8:$N$8,(1+G$6)^-{1,2,3,4,5,6,7,8,9,10})+(('Free Cash Flow Build'!$N$8*(1+$B11))/(G$6-$B11))/(1+G$6)^10)+'Free Cash Flow Build'!$D$20-'Free Cash Flow Build'!$D$19)/'Free Cash Flow Build'!$N$23 -> 150.37535
A12: Grid reproduces the model's DCF mechanics (PV of explicit-period UFCF + PV of Gordon-growth terminal value, net of debt, plus cash, divided by shares outstanding) for each WACC / g pair. Highlighted cell = base case; should equal 'Free Cash Flow Build'!N24.
A14: TABLE 2 — MARGIN OF SAFETY = (INTRINSIC VALUE − MARKET PRICE) / INTRINSIC VALUE
B16: Terminal Growth (g) ↓ / WACC → | C16: =C6 -> 0.13301107 | D16: =D6 -> 0.13801107 | E16: =E6 -> 0.14301107 | F16: =F6 -> 0.14801107 | G16: =G6 -> 0.15301107
B17: =B7 -> 0.04 | C17: =(C7-'Free Cash Flow Build'!$N$26)/C7 -> -1.3397876 | D17: =(D7-'Free Cash Flow Build'!$N$26)/D7 -> -1.5236526 | E17: =(E7-'Free Cash Flow Build'!$N$26)/E7 -> -1.7141583 | F17: =(F7-'Free Cash Flow Build'!$N$26)/F7 -> -1.9113961 | G17: =(G7-'Free Cash Flow Build'!$N$26)/G7 -> -2.1154546
B18: =B8 -> 0.045 | C18: =(C8-'Free Cash Flow Build'!$N$26)/C8 -> -1.2441101 | D18: =(D8-'Free Cash Flow Build'!$N$26)/D8 -> -1.427315 | E18: =(E8-'Free Cash Flow Build'!$N$26)/E8 -> -1.6171909 | F18: =(F8-'Free Cash Flow Build'!$N$26)/F8 -> -1.8138296 | G18: =(G8-'Free Cash Flow Build'!$N$26)/G8 -> -2.0173203
B19: =B9 -> 0.05 | C19: =(C9-'Free Cash Flow Build'!$N$26)/C9 -> -1.145795 | D19: =(D9-'Free Cash Flow Build'!$N$26)/D9 -> -1.3283345 | E19: =(E9-'Free Cash Flow Build'!$N$26)/E9 -> -1.5175763 | F19: =(F9-'Free Cash Flow Build'!$N$26)/F9 -> -1.7136129 | G19: =(G9-'Free Cash Flow Build'!$N$26)/G9 -> -1.9165336
B20: =B10 -> 0.055 | C20: =(C10-'Free Cash Flow Build'!$N$26)/C10 -> -1.0447317 | D20: =(D10-'Free Cash Flow Build'!$N$26)/D10 -> -1.2266009 | E20: =(E10-'Free Cash Flow Build'!$N$26)/E10 -> -1.4152048 | F20: =(F10-'Free Cash Flow Build'!$N$26)/F10 -> -1.6106363 | G20: =(G10-'Free Cash Flow Build'!$N$26)/G10 -> -1.8129854
B21: =B11 -> 0.06 | C21: =(C11-'Free Cash Flow Build'!$N$26)/C11 -> -0.9408034 | D21: =(D11-'Free Cash Flow Build'!$N$26)/D11 -> -1.1219976 | E21: =(E11-'Free Cash Flow Build'!$N$26)/E11 -> -1.3099602 | F21: =(F11-'Free Cash Flow Build'!$N$26)/F11 -> -1.5047845 | G21: =(G11-'Free Cash Flow Build'!$N$26)/G11 -> -1.7065606
A22: Negative values indicate the market price exceeds the DCF's intrinsic value (i.e. the stock screens as overvalued on that assumption pair); positive values indicate a margin of safety. Highlighted cell = base case; should equal 'Free Cash Flow Build'!O28.
A24: BASE-CASE CROSS-CHECK
B26: Model WACC | D26: =Assumptions!$C$28 -> 0.14301107
B27: Model Terminal Growth Rate | D27: ='Free Cash Flow Build'!$O$14 -> 0.05
B28: Model Intrinsic Value / Share (₹) | D28: ='Free Cash Flow Build'!$N$24 -> 161.66342
B29: Sensitivity Table 1 Center Cell (₹) | D29: =E9 -> 161.66342
B30: Model Margin of Safety | D30: ='Free Cash Flow Build'!$O$28 -> -1.5175763
B31: Sensitivity Table 2 Center Cell | D31: =E19 -> -1.5175763
A33: METHODOLOGY NOTES
B34: 1. Both tables recompute the DCF independently for each WACC / Terminal Growth pair; they do not read the single-point output in the Free Cash Flow Build sheet, so every cell is a live, standalone valuation.
B35: 2. Unlevered free cash flow for FY26E–FY35E ('Free Cash Flow Build'!E8:N8) is held constant across the grid — only the discount rate and terminal growth assumption change. Operating assumptions (growth, margin, capex, NWC) are not re-sensitized here.
B36: 3. WACC and Terminal Growth headers are built as the model's current base-case value (Assumptions!C28 and 'Free Cash Flow Build'!O14) plus/minus 0.50 and 1.00 percentage points, so the grid re-centers automatically if the base-case assumptions on those sheets are changed.
B37: 4. Terminal value uses the Gordon growth formula: TV = UFCF(FY35E) × (1+g) / (WACC − g), consistent with 'Free Cash Flow Build'!N15.
B38: 5. Cash, debt and shares outstanding are pulled directly from 'Free Cash Flow Build'!D19, D20 and N23 and are not sensitized.

Sheet Net Working Capital
A1: Particulars | B1: 45261 | C1: 45627 | D1: 45992 | E1: Dec-26E | F1: Dec-27E | G1: Dec-28E | H1: Dec-29E | I1: Dec-30E | J1: Dec-31E | K1: Dec-32E | L1: Dec-33E | M1: Dec-34E | N1: Dec-35E
A2: Inventories | B2: 2151 | C2: 2791 | D2: 2952
A3: Trade Receivables | B3: 359 | C3: 846 | D3: 1249
A4: Other Asset Items | B4: 1612 | C4: 1745 | D4: 1837
A5: Loan and Advances | B5: 253 | C5: 664 | D5: 300
A6: Total Operating Current Assets | B6: =SUM(B2:B5) -> 4375 | C6: =SUM(C2:C5) -> 6046 | D6: =SUM(D2:D5)+1 -> 6339
A8: Trade Paybles | B8: 758 | C8: 1560 | D8: 1401
A9: Advances from Customer | B9: 180 | C9: 219 | D9: 159
A10: Other Liability Items | B10: 1732 | C10: 1778 | D10: 1731
A11: Total Operating Current Liabilities | B11: =SUM(B8:B10)+1 -> 2671 | C11: =SUM(C8:C10)+1 -> 3558 | D11: =SUM(D8:D10)+1 -> 3292
A13: Net Working Capital | B13: =B6-B11 -> 1704 | C13: =C6-C11 -> 2488 | D13: =D6-D11 -> 3047 | E13: ='Income Statement Working'!E2*Assumptions!C11 -> 3083.607 | F13: ='Income Statement Working'!F2*Assumptions!D11 -> 3224.2966 | G13: ='Income Statement Working'!G2*Assumptions!E11 -> 3316.4193 | H13: ='Income Statement Working'!H2*Assumptions!F11 -> 3330.2377 | I13: ='Income Statement Working'!I2*Assumptions!G11 -> 3170.3863 | J13: ='Income Statement Working'!J2*Assumptions!H11 -> 3414.7703 | K13: ='Income Statement Working'!K2*Assumptions!I11 -> 3601.0305 | L13: ='Income Statement Working'!L2*Assumptions!J11 -> 3710.8619 | ... N13: ='Income Statement Working'!N2*Assumptions!L11 -> 4063.8061
A14: Changes in NWC | B14: - | C14: =C13-B13 -> 784 | D14: =D13-C13 -> 559 | E14: =E13-D13 -> 36.607 | F14: =F13-E13 -> 140.68957 | G14: =G13-F13 -> 92.122759 | H14: =H13-G13 -> 13.818414 | I14: =I13-H13 -> -159.85141 | J14: =J13-I13 -> 244.38395 | ... N14: =N13-M13 -> 369.43692
A15: NWC Margin | D15: =D13/'Income Statement Working'!D2 -> 0.14051187
A18: Borrowings/Total Debt | D18: =SUM(540+1484) -> 2024
A19: C&CE | D19: 1998

Sheet Ratios
B1: 42705 | C1: 43070 | D1: 43435 | E1: 43800 | F1: 44166 | G1: 44531 | H1: 44896 | I1: 45261 | J1: 45627 | K1: 45992 | L1: TrendLine | M1: Mean | N1: Median
A2: Sales Growth | C2: =(IncomeStatement!C3-IncomeStatement!B3)/IncomeStatement!B3 -> 0.036853828 | D2: =(IncomeStatement!D3-IncomeStatement!C3)/IncomeStatement!C3 -> 0.27520919 | E2: =(IncomeStatement!E3-IncomeStatement!D3)/IncomeStatement!D3 -> 0.39650951 | F2: =(IncomeStatement!F3-IncomeStatement!E3)/IncomeStatement!E3 -> -0.09530689 | G2: =(IncomeStatement!G3-IncomeStatement!F3)/IncomeStatement!F3 -> 0.36791678 | H2: =(IncomeStatement!H3-IncomeStatement!G3)/IncomeStatement!G3 -> 0.49300707 | I2: =(IncomeStatement!I3-IncomeStatement!H3)/IncomeStatement!H3 -> 0.21783028 | J2: =(IncomeStatement!J3-IncomeStatement!I3)/IncomeStatement!I3 -> 0.24716068 | K2: =(IncomeStatement!K3-IncomeStatement!J3)/IncomeStatement!J3 -> 0.083852717 | M2: =AVERAGE(C2:K2) -> 0.22478146 | N2: =MEDIAN(C2:K2) -> 0.24716068
A3: EBITDA Growth | C3: =(IncomeStatement!C15-IncomeStatement!B15)/IncomeStatement!B15 -> 0.035577517 | D3: =(IncomeStatement!D15-IncomeStatement!C15)/IncomeStatement!C15 -> 0.23559585 | E3: =(IncomeStatement!E15-IncomeStatement!D15)/IncomeStatement!D15 -> 0.41175903 | F3: =(IncomeStatement!F15-IncomeStatement!E15)/IncomeStatement!E15 -> -0.16911714 | G3: =(IncomeStatement!G15-IncomeStatement!F15)/IncomeStatement!F15 -> 0.39423868 | H3: =(IncomeStatement!H15-IncomeStatement!G15)/IncomeStatement!G15 -> 0.69008264 | I3: =(IncomeStatement!I15-IncomeStatement!H15)/IncomeStatement!H15 -> 0.29818372 | J3: =(IncomeStatement!J15-IncomeStatement!I15)/IncomeStatement!I15 -> 0.29639196 | K3: =(IncomeStatement!K15-IncomeStatement!J15)/IncomeStatement!J15 -> 0.052176079 | M3: =AVERAGE(C3:K3) -> 0.24943204 | N3: =MEDIAN(C3:K3) -> 0.29639196
A4: EBIT Growth | C4: =((IncomeStatement!C15-IncomeStatement!C21)-(IncomeStatement!B15-IncomeStatement!B21))/(IncomeStatement!B15-IncomeStatement!B21) -> 0.0090293454 | D4: =((IncomeStatement!D15-IncomeStatement!D21)-(IncomeStatement!C15-IncomeStatement!C21))/(IncomeStatement!C15-IncomeStatement!C21) -> 0.32336791 | E4: =((IncomeStatement!E15-IncomeStatement!E21)-(IncomeStatement!D15-IncomeStatement!D21))/(IncomeStatement!D15-IncomeStatement!D21) -> 0.4963885 | F4: =((IncomeStatement!F15-IncomeStatement!F21)-(IncomeStatement!E15-IncomeStatement!E21))/(IncomeStatement!E15-IncomeStatement!E21) -> -0.29516278 | G4: =((IncomeStatement!G15-IncomeStatement!G21)-(IncomeStatement!F15-IncomeStatement!F21))/(IncomeStatement!F15-IncomeStatement!F21) -> 0.69415707 | H4: =((IncomeStatement!H15-IncomeStatement!H21)-(IncomeStatement!G15-IncomeStatement!G21))/(IncomeStatement!G15-IncomeStatement!G21) -> 0.93153866 | I4: =((IncomeStatement!I15-IncomeStatement!I21)-(IncomeStatement!H15-IncomeStatement!H21))/(IncomeStatement!H15-IncomeStatement!H21) -> 0.35176774 | J4: =((IncomeStatement!J15-IncomeStatement!J21)-(IncomeStatement!I15-IncomeStatement!I21))/(IncomeStatement!I15-IncomeStatement!I21) -> 0.275084 | K4: =((IncomeStatement!K15-IncomeStatement!K21)-(IncomeStatement!J15-IncomeStatement!J21))/(IncomeStatement!J15-IncomeStatement!J21) -> -0.00457258 | M4: =AVERAGE(C4:K4) -> 0.30906643 | N4: =MEDIAN(C4:K4) -> 0.32336791
A5: Net Profit Growth | C5: =(IncomeStatement!C30-IncomeStatement!B30)/IncomeStatement!B30 -> 8.399061 | D5: =(IncomeStatement!D30-IncomeStatement!C30)/IncomeStatement!C30 -> 0.46853147 | E5: =(IncomeStatement!E30-IncomeStatement!D30)/IncomeStatement!D30 -> 0.44659864 | F5: =(IncomeStatement!F30-IncomeStatement!E30)/IncomeStatement!E30 -> -0.089348695 | G5: =(IncomeStatement!G30-IncomeStatement!F30)/IncomeStatement!F30 -> 0.79499096 | H5: =(IncomeStatement!H30-IncomeStatement!G30)/IncomeStatement!G30 -> 1.2557537 | I5: =(IncomeStatement!I30-IncomeStatement!H30)/IncomeStatement!H30 -> 0.34338732 | J5: =(IncomeStatement!J30-IncomeStatement!I30)/IncomeStatement!I30 -> 0.22903119 | K5: =(IncomeStatement!K30-IncomeStatement!J30)/IncomeStatement!J30 -> 0.046539472 | M5: =AVERAGE(C5:K5) -> 1.3216161 | N5: =MEDIAN(C5:K5) -> 0.44659864
A6: Dividend Growth | C6: 0 | D6: =(IncomeStatement!D38-IncomeStatement!C38)/IncomeStatement!C38 -> 0 | E6: =(IncomeStatement!E38-IncomeStatement!D38)/IncomeStatement!D38 -> 0.46666667 | F6: =(IncomeStatement!F38-IncomeStatement!E38)/IncomeStatement!E38 -> 0 | G6: =(IncomeStatement!G38-IncomeStatement!F38)/IncomeStatement!F38 -> 0.5 | H6: =(IncomeStatement!H38-IncomeStatement!G38)/IncomeStatement!G38 -> 1.1212121 | I6: =(IncomeStatement!I38-IncomeStatement!H38)/IncomeStatement!H38 -> 0.42857143 | J6: =(IncomeStatement!J38-IncomeStatement!I38)/IncomeStatement!I38 -> 0 | K6: =(IncomeStatement!K38-IncomeStatement!J38)/IncomeStatement!J38 -> 0.5 | M6: =AVERAGE(C6:K6) -> 0.33516114 | N6: =MEDIAN(C6:K6) -> 0.42857143
A7: EBT Growth | C7: =(IncomeStatement!C24-IncomeStatement!B24)/IncomeStatement!B24 -> 4.2680608 | D7: =(IncomeStatement!D24-IncomeStatement!C24)/IncomeStatement!C24 -> 0.54420787 | E7: =(IncomeStatement!E24-IncomeStatement!D24)/IncomeStatement!D24 -> 0.51764431 | F7: =(IncomeStatement!F24-IncomeStatement!E24)/IncomeStatement!E24 -> -0.39559593 | G7: =(IncomeStatement!G24-IncomeStatement!F24)/IncomeStatement!F24 -> 1.4349045 | H7: =(IncomeStatement!H24-IncomeStatement!G24)/IncomeStatement!G24 -> 1.1363399 | I7: =(IncomeStatement!I24-IncomeStatement!H24)/IncomeStatement!H24 -> 0.34407602 | J7: =(IncomeStatement!J24-IncomeStatement!I24)/IncomeStatement!I24 -> 0.23460389 | K7: =(IncomeStatement!K24-IncomeStatement!J24)/IncomeStatement!J24 -> 0.079486423 | M7: =AVERAGE(C7:K7) -> 0.90708086 | N7: =MEDIAN(C7:K7) -> 0.51764431
A9: Net Profit Margin | B9: =(IncomeStatement!B30/IncomeStatement!B3) -> 0.0055164198 | C9: =(IncomeStatement!C30/IncomeStatement!C3) -> 0.050006245 | D9: =(IncomeStatement!D30/IncomeStatement!D3) -> 0.057587213 | E9: =(IncomeStatement!E30/IncomeStatement!E3) -> 0.059652715 | F9: =(IncomeStatement!F30/IncomeStatement!F3) -> 0.060045581 | G9: =(IncomeStatement!G30/IncomeStatement!G3) -> 0.078792275 | H9: =(IncomeStatement!H30/IncomeStatement!H3) -> 0.11904563 | I9: =(IncomeStatement!I30/IncomeStatement!I3) -> 0.13131911 | ... K9: =(IncomeStatement!K30/IncomeStatement!K3) -> 0.12495504 | M9: =AVERAGE(B9:K9) -> 0.081633041 | N9: =MEDIAN(B9:K9) -> 0.069418928
A10: EBIDTA Margin | B10: =IncomeStatement!B15/IncomeStatement!B3 -> 0.20964985 | C10: =IncomeStatement!C15/IncomeStatement!C3 -> 0.20939178 | D10: =IncomeStatement!D15/IncomeStatement!D3 -> 0.2028872 | E10: =IncomeStatement!E15/IncomeStatement!E3 -> 0.20510267 | F10: =IncomeStatement!F15/IncomeStatement!F3 -> 0.18836917 | G10: =IncomeStatement!G15/IncomeStatement!G3 -> 0.19199383 | H10: =IncomeStatement!H15/IncomeStatement!H3 -> 0.21733685 | I10: =IncomeStatement!I15/IncomeStatement!I3 -> 0.23167691 | ... K10: =IncomeStatement!K15/IncomeStatement!K3 -> 0.23378402 | M10: =AVERAGE(B10:K10) -> 0.21310146 | N10: =MEDIAN(B10:K10) -> 0.20952082
A11: EBIT Marin | B11: =(IncomeStatement!B15-IncomeStatement!B21)/IncomeStatement!B3 -> 0.12620429 | C11: =(IncomeStatement!C15-IncomeStatement!C21)/IncomeStatement!C3 -> 0.12281753 | D11: =(IncomeStatement!D15-IncomeStatement!D21)/IncomeStatement!D3 -> 0.12745578 | E11: =(IncomeStatement!E15-IncomeStatement!E21)/IncomeStatement!E3 -> 0.13657148 | F11: =(IncomeStatement!F15-IncomeStatement!F21)/IncomeStatement!F3 -> 0.10640145 | G11: =(IncomeStatement!G15-IncomeStatement!G21)/IncomeStatement!G3 -> 0.13177759 | H11: =(IncomeStatement!H15-IncomeStatement!H21)/IncomeStatement!H3 -> 0.17048379 | I11: =(IncomeStatement!I15-IncomeStatement!I21)/IncomeStatement!I3 -> 0.18923367 | ... K11: =(IncomeStatement!K15-IncomeStatement!K21)/IncomeStatement!K3 -> 0.17768637 | M11: =AVERAGE(B11:K11) -> 0.14821025 | N11: =MEDIAN(B11:K11) -> 0.13417453
A12: EBT Margin | B12: =IncomeStatement!B24/IncomeStatement!B3 -> 0.013622708 | C12: =IncomeStatement!C24/IncomeStatement!C3 -> 0.069214437 | D12: =IncomeStatement!D24/IncomeStatement!D3 -> 0.083814859 | E12: =IncomeStatement!E24/IncomeStatement!E3 -> 0.091085054 | F12: =IncomeStatement!F24/IncomeStatement!F3 -> 0.06085177 | G12: =IncomeStatement!G24/IncomeStatement!G3 -> 0.10831671 | H12: =IncomeStatement!H24/IncomeStatement!H3 -> 0.15499009 | I12: =IncomeStatement!I24/IncomeStatement!I3 -> 0.17105706 | ... K12: =IncomeStatement!K24/IncomeStatement!K3 -> 0.16865264 | M12: =AVERAGE(B12:K12) -> 0.10909401 | N12: =MEDIAN(B12:K12) -> 0.099700882
A13: Gross Margin | B13: =IncomeStatement!B9/IncomeStatement!B3 -> 0.3602507 | C13: =IncomeStatement!C9/IncomeStatement!C3 -> 0.35364056 | D13: =IncomeStatement!D9/IncomeStatement!D3 -> 0.37049733 | E13: =IncomeStatement!E9/IncomeStatement!E3 -> 0.3610441 | F13: =IncomeStatement!F9/IncomeStatement!F3 -> 0.35112634 | G13: =IncomeStatement!G9/IncomeStatement!G3 -> 0.35303518 | H13: =IncomeStatement!H9/IncomeStatement!H3 -> 0.35872346 | I13: =IncomeStatement!I9/IncomeStatement!I3 -> 0.38043085 | ... K13: =IncomeStatement!K9/IncomeStatement!K3 -> 0.3902718 | M13: =AVERAGE(B13:K13) -> 0.36742182 | N13: =MEDIAN(B13:K13) -> 0.3606474
A15: Sales Expenses % Sales | B15: =IncomeStatement!B12/IncomeStatement!B3 -> 0.15060085 | C15: =IncomeStatement!C12/IncomeStatement!C3 -> 0.1442238 | D15: =IncomeStatement!D12/IncomeStatement!D3 -> 0.16761013 | E15: =IncomeStatement!E12/IncomeStatement!E3 -> 0.15594143 | F15: =IncomeStatement!F12/IncomeStatement!F3 -> 0.16275717 | G15: =IncomeStatement!G12/IncomeStatement!G3 -> 0.16104135 | H15: =IncomeStatement!H12/IncomeStatement!H3 -> 0.14138661 | I15: =IncomeStatement!I12/IncomeStatement!I3 -> 0.14874771 | ... K15: =IncomeStatement!K12/IncomeStatement!K3 -> 0.15648316 | M15: =AVERAGE(B15:K15) -> 0.15431678 | N15: =MEDIAN(B15:K15) -> 0.1551585
A16: Depreciation % Sales | B16: =IncomeStatement!B21/IncomeStatement!B3 -> 0.083445561 | C16: =IncomeStatement!C21/IncomeStatement!C3 -> 0.086574248 | D16: =IncomeStatement!D21/IncomeStatement!D3 -> 0.075431414 | E16: =IncomeStatement!E21/IncomeStatement!E3 -> 0.068531194 | F16: =IncomeStatement!F21/IncomeStatement!F3 -> 0.081967721 | G16: =IncomeStatement!G21/IncomeStatement!G3 -> 0.060216248 | H16: =IncomeStatement!H21/IncomeStatement!H3 -> 0.046853057 | I16: =IncomeStatement!I21/IncomeStatement!I3 -> 0.042443245 | ... K16: =IncomeStatement!K21/IncomeStatement!K3 -> 0.056097651 | M16: =AVERAGE(B16:K16) -> 0.064891211 | N16: =MEDIAN(B16:K16) -> 0.064373721
A17: Operating Income % Sales | B17: =(IncomeStatement!B15-IncomeStatement!B21)/IncomeStatement!B3 -> 0.12620429 | C17: =(IncomeStatement!C15-IncomeStatement!C21)/IncomeStatement!C3 -> 0.12281753 | D17: =(IncomeStatement!D15-IncomeStatement!D21)/IncomeStatement!D3 -> 0.12745578 | E17: =(IncomeStatement!E15-IncomeStatement!E21)/IncomeStatement!E3 -> 0.13657148 | F17: =(IncomeStatement!F15-IncomeStatement!F21)/IncomeStatement!F3 -> 0.10640145 | G17: =(IncomeStatement!G15-IncomeStatement!G21)/IncomeStatement!G3 -> 0.13177759 | H17: =(IncomeStatement!H15-IncomeStatement!H21)/IncomeStatement!H3 -> 0.17048379 | I17: =(IncomeStatement!I15-IncomeStatement!I21)/IncomeStatement!I3 -> 0.18923367 | ... K17: =(IncomeStatement!K15-IncomeStatement!K21)/IncomeStatement!K3 -> 0.17768637 | M17: =AVERAGE(B17:K17) -> 0.14821025 | N17: =MEDIAN(B17:K17) -> 0.13417453
A19: Return On Capital Employeed | B19: =(IncomeStatement!B15-IncomeStatement!B21)/(BS!B3+BS!B4+BS!B5) -> 0.12466104 | C19: =(IncomeStatement!C15-IncomeStatement!C21)/(BS!C3+BS!C4+BS!C5) -> 0.11116638 | D19: =(IncomeStatement!D15-IncomeStatement!D21)/(BS!D3+BS!D4+BS!D5) -> 0.13538199 | E19: =(IncomeStatement!E15-IncomeStatement!E21)/(BS!E3+BS!E4+BS!E5) -> 0.14434594 | F19: =(IncomeStatement!F15-IncomeStatement!F21)/(BS!F3+BS!F4+BS!F5) -> 0.10182342 | G19: =(IncomeStatement!G15-IncomeStatement!G21)/(BS!G3+BS!G4+BS!G5) -> 0.15571805 | H19: =(IncomeStatement!H15-IncomeStatement!H21)/(BS!H3+BS!H4+BS!H5) -> 0.24991654 | I19: =(IncomeStatement!I15-IncomeStatement!I21)/(BS!I3+BS!I4+BS!I5) -> 0.24545998 | ... K19: =(IncomeStatement!K15-IncomeStatement!K21)/(BS!K3+BS!K4+BS!K5) -> 0.17445635 | M19: =AVERAGE(B19:K19) -> 0.164209 | N19: =MEDIAN(B19:K19) -> 0.150032
A20: Retained Earnings | C20: =IncomeStatement!C41 -> 77.20% | D20: =IncomeStatement!D41 -> 84.47% | E20: =IncomeStatement!E41 -> 83.03% | F20: =IncomeStatement!F41 -> 81.37% | G20: =IncomeStatement!G41 -> 84.43% | H20: =IncomeStatement!H41 -> 85.50% | I20: =IncomeStatement!I41 -> 84.58% | J20: =IncomeStatement!J41 -> 86.94% | K20: =IncomeStatement!K41 -> 81.28% | M20: =AVERAGE(B20:K21) -> 0.15862538 | N20: =MEDIAN(B20:K21) -> 0.14275537
A21: Return on Equity | B21: =IncomeStatement!B30/SUM(BS!B3:B4) -> 0.01257676 | C21: =IncomeStatement!C30/SUM(BS!C3:C4) -> 0.1131457 | D21: =IncomeStatement!D30/SUM(BS!D3:D4) -> 0.14711033 | E21: =IncomeStatement!E30/SUM(BS!E3:E4) -> 0.12777911 | F21: =IncomeStatement!F30/SUM(BS!F3:F4) -> 0.10990352 | G21: =IncomeStatement!G30/SUM(BS!G3:G4) -> 0.17039633 | H21: =IncomeStatement!H30/SUM(BS!H3:H4) -> 0.30734556 | I21: =IncomeStatement!I30/SUM(BS!I3:I4) -> 0.30371225 | ... K21: =IncomeStatement!K30/SUM(BS!K3:K4) -> 0.1384004 | M21: =AVERAGE(B21:K21) -> 0.15862538 | N21: =MEDIAN(B21:K21) -> 0.14275537
A22: Interest Coverage Ratio | B22: =(IncomeStatement!B15-IncomeStatement!B21)/IncomeStatement!B18 -> 1.121003 | C22: =(IncomeStatement!C15-IncomeStatement!C21)/IncomeStatement!C18 -> 2.2912395 | D22: =(IncomeStatement!D15-IncomeStatement!D21)/IncomeStatement!D18 -> 2.9205566 | E22: =(IncomeStatement!E15-IncomeStatement!E21)/IncomeStatement!E18 -> 3.0024669 | F22: =(IncomeStatement!F15-IncomeStatement!F21)/IncomeStatement!F18 -> 2.3367382 | G22: =(IncomeStatement!G15-IncomeStatement!G21)/IncomeStatement!G18 -> 5.6169082 | H22: =(IncomeStatement!H15-IncomeStatement!H21)/IncomeStatement!H18 -> 11.00343 | I22: =(IncomeStatement!I15-IncomeStatement!I21)/IncomeStatement!I18 -> 10.410837 | ... K22: =(IncomeStatement!K15-IncomeStatement!K21)/IncomeStatement!K18 -> 19.659184 | M22: =AVERAGE(B22:K22) -> 6.6378308 | N22: =MEDIAN(B22:K22) -> 4.3096875
A24: Debt Turnover Ratio | B24: =IncomeStatement!B3/BS!B15 -> 29.385084 | C24: =IncomeStatement!C3/BS!C15 -> 26.636727 | D24: =IncomeStatement!D3/BS!D15 -> 39.885156 | E24: =IncomeStatement!E3/BS!E15 -> 41.307068 | F24: =IncomeStatement!F3/BS!F15 -> 26.675352 | G24: =IncomeStatement!G3/BS!G15 -> 39.86986 | H24: =IncomeStatement!H3/BS!H15 -> 44.01303 | I24: =IncomeStatement!I3/BS!I15 -> 44.637173 | ... K24: =IncomeStatement!K3/BS!K15 -> 17.36221 | M24: =AVERAGE(B24:K24) -> 33.342702 | N24: =MEDIAN(B24:K24) -> 34.627472
A25: Credit Turnover Ratio | B25: =IncomeStatement!B3/BS!B6 -> 4.2180468 | C25: =IncomeStatement!C3/BS!C6 -> 4.6961877 | D25: =IncomeStatement!D3/BS!D6 -> 4.2844075 | E25: =IncomeStatement!E3/BS!E6 -> 4.3739877 | F25: =IncomeStatement!F3/BS!F6 -> 3.7781748 | G25: =IncomeStatement!G3/BS!G6 -> 4.1760697 | H25: =IncomeStatement!H3/BS!H6 -> 5.0047871 | I25: =IncomeStatement!I3/BS!I6 -> 5.6900759 | ... K25: =IncomeStatement!K3/BS!K6 -> 6.2787075 | M25: =AVERAGE(B25:K25) -> 4.7925232 | N25: =MEDIAN(B25:K25) -> 4.5350877
A26: Inventory Turnover Ratio | B26: =IncomeStatement!B3/BS!B16 -> 7.8816085 | C26: =IncomeStatement!C3/BS!C16 -> 9.1216678 | D26: =IncomeStatement!D3/BS!D16 -> 8.8265906 | E26: =IncomeStatement!E3/BS!E16 -> 8.0880318 | F26: =IncomeStatement!F3/BS!F16 -> 6.9445521 | G26: =IncomeStatement!G3/BS!G16 -> 6.0929494 | H26: =IncomeStatement!H3/BS!H16 -> 6.6067004 | I26: =IncomeStatement!I3/BS!I16 -> 7.4599395 | ... K26: =IncomeStatement!K3/BS!K16 -> 7.3465004 | M26: =AVERAGE(B26:K26) -> 7.5536676 | N26: =MEDIAN(B26:K26) -> 7.40322
A27: Fixed Asset Turnover Ratio | B27: =IncomeStatement!B3/BS!B9 -> 1.0392141 | C27: =IncomeStatement!C3/BS!C9 -> 1.0057782 | D27: =IncomeStatement!D3/BS!D9 -> 1.1637338 | E27: =IncomeStatement!E3/BS!E9 -> 1.1004167 | F27: =IncomeStatement!F3/BS!F9 -> 1.0064757 | G27: =IncomeStatement!G3/BS!G9 -> 1.3981112 | H27: =IncomeStatement!H3/BS!H9 -> 1.900277 | I27: =IncomeStatement!I3/BS!I9 -> 1.9077439 | ... K27: =IncomeStatement!K3/BS!K9 -> 1.2939632 | M27: =AVERAGE(B27:K27) -> 1.3308636 | N27: =MEDIAN(B27:K27) -> 1.2288485
A28: Capital Turnover Ratio | B28: =IncomeStatement!B3/SUM(BS!B3:B4) -> 2.2798772 | C28: =IncomeStatement!C3/SUM(BS!C3:C4) -> 2.2626314 | D28: =IncomeStatement!D3/SUM(BS!D3:D4) -> 2.5545659 | E28: =IncomeStatement!E3/SUM(BS!E3:E4) -> 2.1420502 | F28: =IncomeStatement!F3/SUM(BS!F3:F4) -> 1.8303348 | G28: =IncomeStatement!G3/SUM(BS!G3:G4) -> 2.162602 | H28: =IncomeStatement!H3/SUM(BS!H3:H4) -> 2.5817458 | I28: =IncomeStatement!I3/SUM(BS!I3:I4) -> 2.3127802 | ... K28: =IncomeStatement!K3/SUM(BS!K3:K4) -> 1.1076016 | M28: =AVERAGE(B28:K28) -> 2.0438761 | N28: =MEDIAN(B28:K28) -> 2.2126167
A30: Debtor Days | B30: =(BS!B15/IncomeStatement!B3)*365 -> 12.421268 | C30: =(BS!C15/IncomeStatement!C3)*365 -> 13.702885 | D30: =(BS!D15/IncomeStatement!D3)*365 -> 9.1512742 | E30: =(BS!E15/IncomeStatement!E3)*365 -> 8.8362601 | F30: =(BS!F15/IncomeStatement!F3)*365 -> 13.683044 | G30: =(BS!G15/IncomeStatement!G3)*365 -> 9.1547851 | H30: =(BS!H15/IncomeStatement!H3)*365 -> 8.2929986 | I30: =(BS!I15/IncomeStatement!I3)*365 -> 8.1770411 | ... K30: =(BS!K15/IncomeStatement!K3)*365 -> 21.02267 | M30: =AVERAGE(B30:K30) -> 11.987213 | N30: =MEDIAN(B30:K30) -> 10.788027
A31: Payables Days | B31: =365/B25 -> 86.532943 | C31: =365/C25 -> 77.722618 | D31: =365/D25 -> 85.192643 | E31: =365/E25 -> 83.447879 | F31: =365/F25 -> 96.607494 | G31: =365/G25 -> 87.402756 | H31: =365/H25 -> 72.930176 | I31: =365/I25 -> 64.146772 | ... K31: =365/K25 -> 58.132983 | M31: =AVERAGE(B31:K31) -> 77.940001 | N31: =MEDIAN(B31:K31) -> 80.585248
A32: Inventory Days | B32: =365/B26 -> 46.310344 | C32: =365/C26 -> 40.014612 | D32: =365/D26 -> 41.35232 | E32: =365/E26 -> 45.128408 | F32: =365/F26 -> 52.559185 | G32: =365/G26 -> 59.905306 | H32: =365/H26 -> 55.246943 | I32: =365/I26 -> 48.92801 | ... K32: =365/K26 -> 49.68352 | M32: =AVERAGE(B32:K32) -> 49.004844 | N32: =MEDIAN(B32:K32) -> 49.305765
A33: Cash Conversion Cycle (CCC) | B33: =B30+B32-B31 -> -27.801331 | C33: =C30+C32-C31 -> -24.005121 | D33: =D30+D32-D31 -> -34.689049 | E33: =E30+E32-E31 -> -29.483211 | F33: =F30+F32-F31 -> -30.365266 | G33: =G30+G32-G31 -> -18.342665 | H33: =H30+H32-H31 -> -9.3902346 | I33: =I30+I32-I31 -> -7.0417202 | ... K33: =K30+K32-K31 -> 12.573206 | M33: =AVERAGE(B33:K33) -> -16.947943 | N33: =MEDIAN(B33:K33) -> -21.173893
A35: CFO/Sales | B35: ='Cash Flow Statement'!D3/IncomeStatement!B3 -> 0.21236921 | C35: ='Cash Flow Statement'!E2/IncomeStatement!C3 -> 0.15486449 | D35: ='Cash Flow Statement'!F2/IncomeStatement!D3 -> 0.19587488 | E35: ='Cash Flow Statement'!G2/IncomeStatement!E3 -> 0.1834605 | F35: ='Cash Flow Statement'!H2/IncomeStatement!F3 -> 0.15689679 | G35: ='Cash Flow Statement'!I2/IncomeStatement!G3 -> 0.13951854 | H35: ='Cash Flow Statement'!J2/IncomeStatement!H3 -> 0.13588297 | I35: ='Cash Flow Statement'!K2/IncomeStatement!I3 -> 0.14904068 | J35: ='Cash Flow Statement'!L2/IncomeStatement!J3 -> 0.16898494 | K35: ='Cash Flow Statement'!M2/IncomeStatement!K3 -> 0.16181394 | M35: =AVERAGE(B35:K35) -> 0.1658707 | N35: =MEDIAN(B35:K35) -> 0.15935537
A36: CFO/Total Asset | B36: ='Cash Flow Statement'!D2/BS!B20 -> 0.171213 | C36: ='Cash Flow Statement'!E2/BS!C20 -> 0.11752218 | D36: ='Cash Flow Statement'!F2/BS!D20 -> 0.16672224 | E36: ='Cash Flow Statement'!G2/BS!E20 -> 0.15616792 | F36: ='Cash Flow Statement'!H2/BS!F20 -> 0.11980018 | G36: ='Cash Flow Statement'!I2/BS!G20 -> 0.12850358 | H36: ='Cash Flow Statement'!J2/BS!H20 -> 0.15406862 | I36: ='Cash Flow Statement'!K2/BS!I20 -> 0.15743521 | ... K36: ='Cash Flow Statement'!M2/BS!K20 -> 0.13738856 | M36: =AVERAGE(B36:K36) -> 0.14550313 | N36: =MEDIAN(B36:K36) -> 0.15013922
A37: CFO/Total Debt | B37: ='Cash Flow Statement'!D3/(BS!B5) -> 0.37013632 | C37: ='Cash Flow Statement'!E3/(BS!C5) -> 0.32897464 | D37: ='Cash Flow Statement'!F3/(BS!D5) -> 0.39994302 | E37: ='Cash Flow Statement'!G3/(BS!E5) -> 0.44276015 | F37: ='Cash Flow Statement'!H3/(BS!F5) -> 0.37312273 | G37: ='Cash Flow Statement'!I3/(BS!G5) -> 0.47950868 | H37: ='Cash Flow Statement'!J3/(BS!H5) -> 0.70781194 | I37: ='Cash Flow Statement'!K3/(BS!I5) -> 0.68712831 | ... K37: ='Cash Flow Statement'!M3/(BS!K5) -> 1.981102 | M37: =AVERAGE(B37:K37) -> 0.74610373 | N37: =MEDIAN(B37:K37) -> 0.46113442

Sheet DuPont Analysis
A1: Line Item | B1: Formula | C1: 45261 | D1: 45627 | E1: 45992
A2: Net Profit Margin | B2: Net Income/Sales | C2: ='Income Statement'!K20/'Income Statement'!K2 -> 0.13102288 | D2: ='Income Statement'!L20/'Income Statement'!L2 -> 0.13164734 | E2: ='Income Statement'!M20/'Income Statement'!M2 -> 0.1412036
A3: Asset Turnover Ratio | B3: Sales/Avergae Total Assets | C3: ='Income Statement'!K2/((BalanceSheet!K39+BalanceSheet!J39)/2) -> 1.1970155 | D3: ='Income Statement'!L2/((BalanceSheet!L39+BalanceSheet!K39)/2) -> 1.0445042 | E3: ='Income Statement'!M2/((BalanceSheet!M39+BalanceSheet!L39)/2) -> 0.8911949
A4: Financial Leverage Ratio | B4: Average Total Assets/Average Shareholder's Equity | C4: =((BalanceSheet!K39+BalanceSheet!J39)/2)/((BalanceSheet!K2+BalanceSheet!K3+BalanceSheet!J2+BalanceSheet!J3)/2) -> 2.2263289 | D4: =((BalanceSheet!L39+BalanceSheet!K39)/2)/((BalanceSheet!L2+BalanceSheet!L3+BalanceSheet!K2+BalanceSheet!K3)/2) -> 1.6270013 | E4: =((BalanceSheet!M39+BalanceSheet!L39)/2)/((BalanceSheet!M2+BalanceSheet!M3+BalanceSheet!L2+BalanceSheet!L3)/2) -> 1.3447828
A5: DuPont Analysis | B5: Net Profit Margin * Asset Turnover Ratio * Financail Leverage Ratio | C5: =C2*C3*C4 -> 0.34916944 | D5: =D2*D3*D4 -> 0.22372277 | E5: =E2*E3*E4 -> 0.16922737
A6: ROE | B6: Net Income/Average Shareholder's Equity | C6: ='Income Statement'!K20/((BalanceSheet!K2+BalanceSheet!K3+BalanceSheet!J2+BalanceSheet!J3)/2) -> 0.34916944 | D6: ='Income Statement'!L20/((BalanceSheet!L2+BalanceSheet!L3+BalanceSheet!K2+BalanceSheet!K3)/2) -> 0.22372277 | E6: ='Income Statement'!M20/((BalanceSheet!M2+BalanceSheet!M3+BalanceSheet!L2+BalanceSheet!L3)/2) -> 0.16922737
A7: The 5-Step DuPont
A8: Line Item | B8: Formula | C8: 45261 | D8: 45627 | E8: 45992
A9: Tax Burden | B9: Net Income/Profit Befor Tax | C9: ='Income Statement'!K20/'Income Statement'!K18 -> 0.76743337 | D9: ='Income Statement'!L20/'Income Statement'!L18 -> 0.76725896 | E9: ='Income Statement'!M20/'Income Statement'!M18 -> 0.76359102
A10: Interest Burden | B10: Profit Before Tax/EBIT | C10: ='Income Statement'!K18/('Income Statement'!K18+'Income Statement'!K16) -> 0.90366216 | D10: ='Income Statement'!L18/('Income Statement'!L18+'Income Statement'!L16) -> 0.87665986 | E10: ='Income Statement'!M18/('Income Statement'!M18+'Income Statement'!M16) -> 0.9533999
A11: EBIT Margin | B11: EBIT/Sales | C11: =('Income Statement'!K18+'Income Statement'!K16)/'Income Statement'!K2 -> 0.18892975 | D11: =('Income Statement'!L18+'Income Statement'!L16)/'Income Statement'!L2 -> 0.19572171 | E11: =('Income Statement'!M18+'Income Statement'!M16)/'Income Statement'!M2 -> 0.19395896
A12: ROE | B12: Tax Burden * Interest Burden * EBIT Margin * Asset Turnover Ratio * Financial Leverage Ratio | C12: =C9*C10*C11*C3*C4 -> 0.34916944 | D12: =D9*D10*D11*D3*D4 -> 0.22372277 | E12: =E9*E10*E11*E3*E4 -> 0.16922737
A14: ROA | B14: Net Income/Average Total Assets | C14: ='Income Statement'!K20/((BalanceSheet!K39+BalanceSheet!J39)/2) -> 0.15683641 | D14: ='Income Statement'!L20/((BalanceSheet!L39+BalanceSheet!K39)/2) -> 0.1375062 | E14: ='Income Statement'!M20/((BalanceSheet!M39+BalanceSheet!L39)/2) -> 0.12583993
A15: ROA | B15: Net Profit Margin * Assest Turnover Ratio | C15: =C2*C3 -> 0.15683641 | D15: =D2*D3 -> 0.1375062 | E15: =E2*E3 -> 0.12583993

Sheet BalanceSheet
A1: Particulars | B1: 41974 | C1: 42339 | D1: 42705 | E1: 43070 | F1: 43435 | G1: 43800 | H1: 44166 | I1: 44531 | J1: 44896 | K1: 45261 | L1: 45627 | M1: 45992
A2: Equity Capital | B2: 134 | C2: 134 | D2: 182 | E2: 183 | F2: 183 | G2: 289 | H2: 289 | I2: 433 | J2: 650 | K2: 650 | L2: 676 | M2: 676
A3: Reserves | B3: 9 | C3: 91 | D3: 1511 | E3: 1587 | F3: 1816 | G3: 3040 | H3: 3235 | I3: 3647 | J3: 4453 | K3: 6287 | L3: 15934 | M3: 18902
A4: Borrowings | B4: 2615 | C4: 2527 | D4: 2215 | E4: 2654 | F4: 2808 | G4: 3417 | H4: 3216 | I4: 3387 | J4: 3884 | K4: 5431 | L4: 2826 | M4: 2508
A5: Long term Borrowings | B5: 1623 | C5: 1580 | D5: 1218 | E5: 1691 | F5: 1980 | G5: 2355 | H5: 1980 | I5: 1813 | J5: 1727 | K5: 3189 | L5: 841 | M5: 540
A6: Short term Borrowings | B6: 509 | C6: 252 | D6: 411 | E6: 353 | F6: 378 | G6: 467 | H6: 714 | I6: 1529 | J6: 1968 | K6: 2005 | L6: 1524 | M6: 1484
A7: Lease Liabilities | B7: 0 | C7: 0 | D7: 0 | E7: 0 | F7: 0 | G7: 0 | H7: 0 | I7: 45 | J7: 189 | K7: 237 | L7: 462 | M7: 484
A8: Preference Capital | B8: 200 | C8: 450 | D8: 0 | E8: 0 | F8: 0 | G8: 0 | H8: 0 | I8: 0 | J8: 0 | K8: 0 | L8: 0 | M8: 0
A9: Other Borrowings | B9: 284 | C9: 245 | D9: 586 | E9: 609 | F9: 450 | G9: 595 | H9: 523 | I9: 0 | J9: 0 | K9: 0 | L9: 0 | M9: 0
A10: Other Liabilities | B10: 533 | C10: 1680 | D10: 915 | E10: 852 | F10: 1192 | G10: 1630 | H10: 1707 | I10: 2113 | J10: 2632 | K10: 2819 | L10: 3688 | M10: 3454
A11: Non controlling int | B11: 0 | C11: 0 | D11: -13 | E11: -1 | F11: 8 | G11: 31 | H11: 65 | I11: 117 | J11: 113 | K11: 148 | L11: 130 | M11: 162
A12: Trade Payables | B12: 181 | C12: 185 | D12: 275 | E12: 191 | F12: 317 | G12: 478 | H12: 511 | I12: 712 | J12: 824 | K12: 758 | L12: 1560 | M12: 1401
... A39: Total Assets | B39: 3292 | C39: 4431 | D39: 4824 | E39: 5276 | F39: 5998 | G39: 8376 | H39: 8447 | I39: 9579 | J39: 11618 | K39: 15187 | L39: 23124 | M39: 25541
A53: 2016 | B53: 307.67 | C53: 3.076 | D53: =B53*C53 -> 946.39292
A54: 2017 | B54: 308.15 | C54: 3.081 | D54: =B54*C54 -> 949.41015
A55: 2018 | B55: 308.21 | C55: 3.082 | D55: =B55*C55 -> 949.90322
A56: 2019 | B56: 324.77 | C56: 3.247 | D56: =B56*C56 -> 1054.5282
A57: 2020 | B57: 324.77 | C57: 3.247 | D57: =B57*C57 -> 1054.5282
A58: 2021 | B58: 324.78 | C58: 3.247 | D58: =B58*C58 -> 1054.5607
A59: 2022 | B59: 324.78 | C59: 3.247 | D59: =B59*C59 -> 1054.5607
A60: 2023 | B60: 324.8 | C60: 3.248 | D60: =B60*C60 -> 1054.9504
A61: 2024 | B61: 338.15 | C61: 3.381 | D61: =B61*C61 -> 1143.2851
A62: 2025 | B62: 338.2 | C62: 3.382 | D62: =B62*C62 -> 1143.7924

Sheet BS
A1: Years | B1: Dec-16 | C1: Dec-17 | D1: Dec-18 | E1: Dec-19 | F1: Dec-20 | G1: Dec-21 | H1: Dec-22 | I1: Dec-23 | J1: Dec-24 | K1: Dec-25
A2: # Balance Sheet
A3: Equity Share Capital | B3: 182.3 | C3: 182.6 | D3: 182.6 | E3: 288.7 | F3: 288.7 | G3: 433 | H3: 649.6 | I3: 649.6 | J3: 676.3 | K3: 676.4
A4: Reserves | B4: 1511.3 | C4: 1586.8 | D4: 1815.9 | E4: 3039.7 | F4: 3235.3 | G4: 3646.9 | H4: 4452.8 | I4: 6286.9 | J4: 15933.5 | K4: 18902.3
A5: Borrowings | B5: 2215.4 | C5: 2653.7 | D5: 2807.9 | E5: 3417.2 | F5: 3216.1 | G5: 3386.8 | H5: 3883.8 | I5: 5431.3 | J5: 2826.3 | K5: 2508.2
A6: Other Liabilities | B6: 915.4 | C6: 852.5 | D6: 1191.6 | E6: 1630 | F6: 1707.2 | G6: 2112.8 | H6: 2632.1 | I6: 2819.4 | J6: 3688.2 | K6: 3453.8
A7: Total Liabilities | B7: 4824.4 | C7: 5275.6 | D7: 5998 | E7: 8375.6 | F7: 8447.4 | G7: 9579.5 | H7: 11618.2 | I7: 15187.2 | J7: 23124.3 | K7: 25540.7
A9: Fixed Assets Net Block | B9: 3715.5 | C9: 3980.5 | D9: 4387 | E9: 6479 | F9: 6408.6 | G9: 6310.8 | H9: 6932.2 | I9: 8409.2 | J9: 13401.7 | K9: 16758.9
A10: Capital Work in Progress | B10: 95.6 | C10: 145.4 | D10: 352.4 | E10: 63.8 | F10: 66.8 | G10: 496.6 | H10: 606.6 | I10: 1922.2 | J10: 1166.7 | K10: 270.8
A11: Investments | B11: 6.9 | C11: 8.2 | D11: 11.2 | E11: 0 | F11: 0 | G11: 0 | H11: 0 | I11: 21.1 | J11: 59.5 | K11: 174.3
A12: Other Assets | B12: 319.5 | C12: 457.8 | D12: 447.5 | E12: 607.6 | F12: 611.3 | G12: 766.1 | H12: 1500.9 | I12: 1864.9 | J12: 2409.2 | K12: 2137.4
A13: Total Non Current Assets | B13: 4137.4 | C13: 4592 | D13: 5198.1 | E13: 7150.4 | F13: 7086.7 | G13: 7573.5 | H13: 9039.7 | I13: 12217.4 | J13: 17037.2 | K13: 19341.4
A15: Receivables | B15: 131.4 | C15: 150.3 | D15: 128 | E15: 172.6 | F15: 241.8 | G15: 221.3 | H15: 299.3 | I15: 359.4 | J15: 845.8 | K15: 1249
A16: Inventory | B16: 489.9 | C16: 438.9 | D16: 578.4 | E16: 881.5 | F16: 928.8 | G16: 1448.1 | H16: 1993.9 | I16: 2150.5 | J16: 2791.2 | K16: 2951.8
... A20: Total Assets | B20: 4824.4 | C20: 5275.6 | D20: 5998 | E20: 8375.6 | F20: 8447.4 | G20: 9579.5 | H20: 11618.2 | I20: 15187.2 | J20: 23124.3 | K20: 25540.7
A22: Check | B22: TRUE | C22: TRUE | D22: TRUE | E22: TRUE | F22: TRUE | G22: TRUE | H22: TRUE | I22: TRUE | J22: TRUE | K22: TRUE

Sheet Commonsize BS
A1: Particulars | B1: 41974 | C1: 42339 | D1: 42705 | E1: 43070 | F1: 43435 | G1: 43800 | H1: 44166 | I1: 44531 | J1: 44896 | K1: 45261 | L1: 45627 | M1: 45992
A2: Equity Capital | B2: =(BalanceSheet!B2/BalanceSheet!$B$39) -> 0.040704739 | C2: =(BalanceSheet!C2/BalanceSheet!$C$39) -> 0.03024148 | D2: =(BalanceSheet!D2/BalanceSheet!$D$39) -> 0.037728027 | E2: =(BalanceSheet!E2/BalanceSheet!$E$39) -> 0.034685368 | F2: =(BalanceSheet!F2/BalanceSheet!$F$39) -> 0.03051017 | G2: =(BalanceSheet!G2/BalanceSheet!$G$39) -> 0.034503343 | H2: =(BalanceSheet!H2/BalanceSheet!$H$39) -> 0.03421333 | I2: =(BalanceSheet!I2/BalanceSheet!$I$39) -> 0.045203048 | J2: =(BalanceSheet!J2/BalanceSheet!$J$39) -> 0.055947667 | K2: =(BalanceSheet!K2/BalanceSheet!$K$39) -> 0.042799763 | L2: =(BalanceSheet!L2/BalanceSheet!$L$39) -> 0.029233697 | M2: =(BalanceSheet!M2/BalanceSheet!$M$39) -> 0.026467249
A3: Reserves | B3: =(BalanceSheet!B3/BalanceSheet!$B$39) -> 0.0027339004 | C3: =(BalanceSheet!C3/BalanceSheet!$C$39) -> 0.020537125 | D3: =(BalanceSheet!D3/BalanceSheet!$D$39) -> 0.31322554 | E3: =(BalanceSheet!E3/BalanceSheet!$E$39) -> 0.30079606 | F3: =(BalanceSheet!F3/BalanceSheet!$F$39) -> 0.30276759 | G3: =(BalanceSheet!G3/BalanceSheet!$G$39) -> 0.36294174 | H3: =(BalanceSheet!H3/BalanceSheet!$H$39) -> 0.3829762 | I3: =(BalanceSheet!I3/BalanceSheet!$I$39) -> 0.38072868 | J3: =(BalanceSheet!J3/BalanceSheet!$J$39) -> 0.38328456 | K3: =(BalanceSheet!K3/BalanceSheet!$K$39) -> 0.41397248 | L3: =(BalanceSheet!L3/BalanceSheet!$L$39) -> 0.68906764 | M3: =(BalanceSheet!M3/BalanceSheet!$M$39) -> 0.74006499
A4: Borrowings | B4: =(BalanceSheet!B4/BalanceSheet!$B$39) -> 0.79434994 | C4: =(BalanceSheet!C4/BalanceSheet!$C$39) -> 0.57030016 | D4: =(BalanceSheet!D4/BalanceSheet!$D$39) -> 0.45916252 | E4: =(BalanceSheet!E4/BalanceSheet!$E$39) -> 0.5030326 | F4: =(BalanceSheet!F4/BalanceSheet!$F$39) -> 0.46815605 | G4: =(BalanceSheet!G4/BalanceSheet!$G$39) -> 0.40795129 | H4: =(BalanceSheet!H4/BalanceSheet!$H$39) -> 0.38072689 | I4: =(BalanceSheet!I4/BalanceSheet!$I$39) -> 0.35358597 | J4: =(BalanceSheet!J4/BalanceSheet!$J$39) -> 0.33430883 | K4: =(BalanceSheet!K4/BalanceSheet!$K$39) -> 0.35760848 | L4: =(BalanceSheet!L4/BalanceSheet!$L$39) -> 0.12221069 | M4: =(BalanceSheet!M4/BalanceSheet!$M$39) -> 0.098195059
A5: Long term Borrowings | B5: =(BalanceSheet!B5/BalanceSheet!$B$39) -> 0.49301337 | C5: =(BalanceSheet!C5/BalanceSheet!$C$39) -> 0.35657865 | D5: =(BalanceSheet!D5/BalanceSheet!$D$39) -> 0.25248756 | E5: =(BalanceSheet!E5/BalanceSheet!$E$39) -> 0.32050796 | F5: =(BalanceSheet!F5/BalanceSheet!$F$39) -> 0.33011004 | G5: =(BalanceSheet!G5/BalanceSheet!$G$39) -> 0.28116046 | H5: =(BalanceSheet!H5/BalanceSheet!$H$39) -> 0.23440275 | I5: =(BalanceSheet!I5/BalanceSheet!$I$39) -> 0.18926819 | J5: =(BalanceSheet!J5/BalanceSheet!$J$39) -> 0.14864865 | K5: =(BalanceSheet!K5/BalanceSheet!$K$39) -> 0.20998222 | L5: =(BalanceSheet!L5/BalanceSheet!$L$39) -> 0.03636914 | M5: =(BalanceSheet!M5/BalanceSheet!$M$39) -> 0.021142477
A6: Short term Borrowings | B6: =(BalanceSheet!B6/BalanceSheet!$B$39) -> 0.15461725 | C6: =(BalanceSheet!C6/BalanceSheet!$C$39) -> 0.056872038 | D6: =(BalanceSheet!D6/BalanceSheet!$D$39) -> 0.085199005 | E6: =(BalanceSheet!E6/BalanceSheet!$E$39) -> 0.066906748 | F6: =(BalanceSheet!F6/BalanceSheet!$F$39) -> 0.063021007 | G6: =(BalanceSheet!G6/BalanceSheet!$G$39) -> 0.055754537 | H6: =(BalanceSheet!H6/BalanceSheet!$H$39) -> 0.084527051 | I6: =(BalanceSheet!I6/BalanceSheet!$I$39) -> 0.15962 | J6: =(BalanceSheet!J6/BalanceSheet!$J$39) -> 0.16939232 | K6: =(BalanceSheet!K6/BalanceSheet!$K$39) -> 0.13202081 | L6: =(BalanceSheet!L6/BalanceSheet!$L$39) -> 0.065905553 | M6: =(BalanceSheet!M6/BalanceSheet!$M$39) -> 0.058102658
A7: Lease Liabilities | B7: =(BalanceSheet!B7/BalanceSheet!$B$39) -> 0 | C7: =(BalanceSheet!C7/BalanceSheet!$C$39) -> 0 | D7: =(BalanceSheet!D7/BalanceSheet!$D$39) -> 0 | E7: =(BalanceSheet!E7/BalanceSheet!$E$39) -> 0 | F7: =(BalanceSheet!F7/BalanceSheet!$F$39) -> 0 | G7: =(BalanceSheet!G7/BalanceSheet!$G$39) -> 0 | H7: =(BalanceSheet!H7/BalanceSheet!$H$39) -> 0 | I7: =(BalanceSheet!I7/BalanceSheet!$I$39) -> 0.0046977764 | J7: =(BalanceSheet!J7/BalanceSheet!$J$39) -> 0.01626786 | K7: =(BalanceSheet!K7/BalanceSheet!$K$39) -> 0.015605452 | L7: =(BalanceSheet!L7/BalanceSheet!$L$39) -> 0.019979242 | M7: =(BalanceSheet!M7/BalanceSheet!$M$39) -> 0.018949924
A8: Preference Capital | B8: =(BalanceSheet!B8/BalanceSheet!$B$39) -> 0.060753341 | C8: =(BalanceSheet!C8/BalanceSheet!$C$39) -> 0.10155721 | D8: =(BalanceSheet!D8/BalanceSheet!$D$39) -> 0 | E8: =(BalanceSheet!E8/BalanceSheet!$E$39) -> 0 | F8: =(BalanceSheet!F8/BalanceSheet!$F$39) -> 0 | G8: =(BalanceSheet!G8/BalanceSheet!$G$39) -> 0 | H8: =(BalanceSheet!H8/BalanceSheet!$H$39) -> 0 | I8: =(BalanceSheet!I8/BalanceSheet!$I$39) -> 0 | J8: =(BalanceSheet!J8/BalanceSheet!$J$39) -> 0 | K8: =(BalanceSheet!K8/BalanceSheet!$K$39) -> 0 | L8: =(BalanceSheet!L8/BalanceSheet!$L$39) -> 0 | M8: =(BalanceSheet!M8/BalanceSheet!$M$39) -> 0
A9: Other Borrowings | B9: =(BalanceSheet!B9/BalanceSheet!$B$39) -> 0.086269745 | C9: =(BalanceSheet!C9/BalanceSheet!$C$39) -> 0.055292259 | D9: =(BalanceSheet!D9/BalanceSheet!$D$39) -> 0.12147595 | E9: =(BalanceSheet!E9/BalanceSheet!$E$39) -> 0.11542835 | F9: =(BalanceSheet!F9/BalanceSheet!$F$39) -> 0.075025008 | G9: =(BalanceSheet!G9/BalanceSheet!$G$39) -> 0.071036294 | H9: =(BalanceSheet!H9/BalanceSheet!$H$39) -> 0.061915473 | I9: =(BalanceSheet!I9/BalanceSheet!$I$39) -> 0 | J9: =(BalanceSheet!J9/BalanceSheet!$J$39) -> 0 | K9: =(BalanceSheet!K9/BalanceSheet!$K$39) -> 0 | L9: =(BalanceSheet!L9/BalanceSheet!$L$39) -> 0 | M9: =(BalanceSheet!M9/BalanceSheet!$M$39) -> 0
A10: Other Liabilities | B10: =(BalanceSheet!B10/BalanceSheet!$B$39) -> 0.16190765 | C10: =(BalanceSheet!C10/BalanceSheet!$C$39) -> 0.37914692 | D10: =(BalanceSheet!D10/BalanceSheet!$D$39) -> 0.18967662 | E10: =(BalanceSheet!E10/BalanceSheet!$E$39) -> 0.16148597 | F10: =(BalanceSheet!F10/BalanceSheet!$F$39) -> 0.19873291 | G10: =(BalanceSheet!G10/BalanceSheet!$G$39) -> 0.19460363 | H10: =(BalanceSheet!H10/BalanceSheet!$H$39) -> 0.20208358 | I10: =(BalanceSheet!I10/BalanceSheet!$I$39) -> 0.2205867 | J10: =(BalanceSheet!J10/BalanceSheet!$J$39) -> 0.22654502 | K10: =(BalanceSheet!K10/BalanceSheet!$K$39) -> 0.18561928 | L10: =(BalanceSheet!L10/BalanceSheet!$L$39) -> 0.15948798 | M10: =(BalanceSheet!M10/BalanceSheet!$M$39) -> 0.13523355
